<!--
    Made    : Jihyeok Choi
    Dates   : 04-13-2022
    - Two poles
-->
<mujoco model="example">
    <compiler coordinate="global"/>
    <default>
        <geom rgba=".8 .6 .4 1"/>
    </default>
    <asset>
        <texture type="skybox" builtin="gradient" rgb1="1 1 1" rgb2=".6 .8 1"
                 width="256" height="256"/>
    </asset>
    <worldbody>
        <light pos="0 1 1" dir="0 -1 -1" diffuse="1 1 1"/>
<!--        camera setting -->
        <camera name="fixed" pos="0 -1.5 2" xyaxes='1 0 0 0 1 1'/>
        <body name="pole1">
            <geom name="cap1" type="capsule" fromto="0 0 1  0 0 0.6" size="0.01"/>
            <body name="pole2">
                <geom name="cap2" type="capsule" fromto="0 0 0.6  0.3 0 0.6" size="0.01"/>
                <joint name="yHinge" type="hinge" pos="0 0 0.6" axis="0 1 0"/>
            </body>
        </body>
    </worldbody>
    <actuator>
		<motor name="torque" joint="yHinge" gear="1" ctrlrange="-100 100" ctrllimited="true"/>
		<position name="position_servo" joint="yHinge" kp="0"/>
		<velocity name="velocity_servo" joint="yHinge" kv="0"/>
	</actuator>
</mujoco>

